Workbook

Sheet Reseller
A1: Kode Reseller | B1: Reseller Name | C1: Group | D1: Upline | E1: Daftar | F1: Leveling | G1: Agen id | H1: Agen Name | I1: Tipe | J1: Cabang | K1: Short | L1: Sales
A2: OP00011 | B2: Rizly | C2: MK - Marketing | D2: OP00002 | E2: 44702.701 | F2: AGEN | G2: OP00011 | H2: =UPPER(Table3[[#This Row],[Agen id]]&"-"&VLOOKUP(Table3[[#This Row],[Agen id]],A:B,2,0)&"("&Table3[[#This Row],[Short]]&")") | J2: =VLOOKUP(Table3[[#This Row],[Agen id]],Agen!A:C,3,0) | K2: =TRIM(LEFT(Table3[[#This Row],[Group]],2)) | L2: NON SALES
A3: OP00012 | B3: Sans Cell | C3: A - Agen | D3: OP00002 | E3: 44702.749 | F3: AGEN | G3: OP00012 | H3: =UPPER(Table3[[#This Row],[Agen id]]&"-"&VLOOKUP(Table3[[#This Row],[Agen id]],A:B,2,0)&"("&Table3[[#This Row],[Short]]&")") | J3: =VLOOKUP(Table3[[#This Row],[Agen id]],Agen!A:C,3,0) | K3: =TRIM(LEFT(Table3[[#This Row],[Group]],2)) | L3: NON SALES
A4: OP00013 | B4: SRH CELL | C4: A - Agen | D4: OP00002 | E4: 44704.432 | F4: AGEN | G4: OP00013 | H4: =UPPER(Table3[[#This Row],[Agen id]]&"-"&VLOOKUP(Table3[[#This Row],[Agen id]],A:B,2,0)&"("&Table3[[#This Row],[Short]]&")") | J4: =VLOOKUP(Table3[[#This Row],[Agen id]],Agen!A:C,3,0) | K4: =TRIM(LEFT(Table3[[#This Row],[Group]],2)) | L4: NON SALES
A5: OP00014 | B5: Data Cellular | C5: AT1 - Agen Tangerang | D5: OP00002 | E5: 44704.435 | F5: AGEN | G5: OP00014 | H5: =UPPER(Table3[[#This Row],[Agen id]]&"-"&VLOOKUP(Table3[[#This Row],[Agen id]],A:B,2,0)&"("&Table3[[#This Row],[Short]]&")") | J5: =VLOOKUP(Table3[[#This Row],[Agen id]],Agen!A:C,3,0) | K5: =TRIM(LEFT(Table3[[#This Row],[Group]],2)) | L5: NON SALES
A6: OP00015 | B6: Naira Cell | C6: AV - Agen Verified | D6: OP00002 | E6: 44705.451 | F6: AGEN | G6: OP00015 | H6: =UPPER(Table3[[#This Row],[Agen id]]&"-"&VLOOKUP(Table3[[#This Row],[Agen id]],A:B,2,0)&"("&Table3[[#This Row],[Short]]&")") | J6: =VLOOKUP(Table3[[#This Row],[Agen id]],Agen!A:C,3,0) | K6: =TRIM(LEFT(Table3[[#This Row],[Group]],2)) | L6: NON SALES
A7: OP00016 | B7: Sabiq Cell | C7: A - Agen | D7: OP00002 | E7: 44705.451 | F7: AGEN | G7: OP00016 | H7: =UPPER(Table3[[#This Row],[Agen id]]&"-"&VLOOKUP(Table3[[#This Row],[Agen id]],A:B,2,0)&"("&Table3[[#This Row],[Short]]&")") | J7: =VLOOKUP(Table3[[#This Row],[Agen id]],Agen!A:C,3,0) | K7: =TRIM(LEFT(Table3[[#This Row],[Group]],2)) | L7: NON SALES
A8: OP00018 | B8: OkiOke Cell | C8: A - Agen | D8: OP00002 | E8: 44708.611 | F8: AGEN | G8: OP00018 | H8: =UPPER(Table3[[#This Row],[Agen id]]&"-"&VLOOKUP(Table3[[#This Row],[Agen id]],A:B,2,0)&"("&Table3[[#This Row],[Short]]&")") | J8: =VLOOKUP(Table3[[#This Row],[Agen id]],Agen!A:C,3,0) | K8: =TRIM(LEFT(Table3[[#This Row],[Group]],2)) | L8: NON SALES
A9: OP00020 | B9: Cantik cell | C9: A - Agen | D9: OP00002 | E9: 44714.407 | F9: AGEN | G9: OP00020 | H9: =UPPER(Table3[[#This Row],[Agen id]]&"-"&VLOOKUP(Table3[[#This Row],[Agen id]],A:B,2,0)&"("&Table3[[#This Row],[Short]]&")") | J9: =VLOOKUP(Table3[[#This Row],[Agen id]],Agen!A:C,3,0) | K9: =TRIM(LEFT(Table3[[#This Row],[Group]],2)) | L9: NON SALES
A10: OP00022 | B10: Fazila store | C10: A - Agen | D10: OP00002 | E10: 44714.419 | F10: AGEN | G10: OP00022 | H10: =UPPER(Table3[[#This Row],[Agen id]]&"-"&VLOOKUP(Table3[[#This Row],[Agen id]],A:B,2,0)&"("&Table3[[#This Row],[Short]]&")") | J10: =VLOOKUP(Table3[[#This Row],[Agen id]],Agen!A:C,3,0) | K10: =TRIM(LEFT(Table3[[#This Row],[Group]],2)) | L10: NON SALES
A11: OP00023 | B11: Mp cell | C11: MK - Marketing | D11: OP00002 | E11: 44714.466 | F11: AGEN | G11: OP00023 | H11: =UPPER(Table3[[#This Row],[Agen id]]&"-"&VLOOKUP(Table3[[#This Row],[Agen id]],A:B,2,0)&"("&Table3[[#This Row],[Short]]&")") | J11: =VLOOKUP(Table3[[#This Row],[Agen id]],Agen!A:C,3,0) | K11: =TRIM(LEFT(Table3[[#This Row],[Group]],2)) | L11: NON SALES
A12: OP00026 | B12: DIKA CELL | C12: A - Agen | D12: OP00002 | E12: 44714.595 | F12: AGEN | G12: OP00026 | H12: =UPPER(Table3[[#This Row],[Agen id]]&"-"&VLOOKUP(Table3[[#This Row],[Agen id]],A:B,2,0)&"("&Table3[[#This Row],[Short]]&")") | J12: =VLOOKUP(Table3[[#This Row],[Agen id]],Agen!A:C,3,0) | K12: =TRIM(LEFT(Table3[[#This Row],[Group]],2)) | L12: NON SALES
A13: OP00030 | B13: Usup | C13: A - Agen | D13: OP00002 | E13: 44716.413 | F13: AGEN | G13: OP00030 | H13: =UPPER(Table3[[#This Row],[Agen id]]&"-"&VLOOKUP(Table3[[#This Row],[Agen id]],A:B,2,0)&"("&Table3[[#This Row],[Short]]&")") | J13: =VLOOKUP(Table3[[#This Row],[Agen id]],Agen!A:C,3,0) | K13: =TRIM(LEFT(Table3[[#This Row],[Group]],2)) | L13: NON SALES
... A2020: OP13613 | B2020: Muh fajar | C2020: A - Agen | D2020: OP10856 | E2020: 45488.597 | F2020: DOWNLINE | G2020: OP10856 | H2020: =UPPER(Table3[[#This Row],[Agen id]]&"-"&VLOOKUP(Table3[[#This Row],[Agen id]],A:B,2,0)&"("&Table3[[#This Row],[Short]]&")") | J2020: =VLOOKUP(Table3[[#This Row],[Agen id]],Agen!A:C,3,0) | K2020: =TRIM(LEFT(Table3[[#This Row],[Group]],2)) | L2020: NON SALES
A2021: OP13614 | B2021: Fajar | C2021: A - Agen | D2021: 0 | E2021: 45488.601 | F2021: AGEN | G2021: OP13614 | H2021: =UPPER(Table3[[#This Row],[Agen id]]&"-"&VLOOKUP(Table3[[#This Row],[Agen id]],A:B,2,0)&"("&Table3[[#This Row],[Short]]&")") | J2021: =VLOOKUP(Table3[[#This Row],[Agen id]],Agen!A:C,3,0) | K2021: =TRIM(LEFT(Table3[[#This Row],[Group]],2)) | L2021: NON SALES
A2022: OP13615 | B2022: lasny simagunsong | C2022: AV - Agen Verified | D2022: OP01449 | E2022: 45488.613 | F2022: DOWNLINE | G2022: OP01449 | H2022: =UPPER(Table3[[#This Row],[Agen id]]&"-"&VLOOKUP(Table3[[#This Row],[Agen id]],A:B,2,0)&"("&Table3[[#This Row],[Short]]&")") | J2022: =VLOOKUP(Table3[[#This Row],[Agen id]],Agen!A:C,3,0) | K2022: =TRIM(LEFT(Table3[[#This Row],[Group]],2)) | L2022: NON SALES
A2023: OP13664 | B2023: Ayda | C2023: A - Agen | D2023: OP03527 | E2023: 45490.721 | F2023: DOWNLINE | G2023: OP02195 | H2023: =UPPER(Table3[[#This Row],[Agen id]]&"-"&VLOOKUP(Table3[[#This Row],[Agen id]],A:B,2,0)&"("&Table3[[#This Row],[Short]]&")") | J2023: =VLOOKUP(Table3[[#This Row],[Agen id]],Agen!A:C,3,0) | K2023: =TRIM(LEFT(Table3[[#This Row],[Group]],2)) | L2023: NON SALES
A2024: OP13685 | B2024: Setiya | C2024: A - Agen | D2024: OP00002 | E2024: 45491.565 | F2024: AGEN | G2024: OP13685 | H2024: =UPPER(Table3[[#This Row],[Agen id]]&"-"&VLOOKUP(Table3[[#This Row],[Agen id]],A:B,2,0)&"("&Table3[[#This Row],[Short]]&")") | J2024: =VLOOKUP(Table3[[#This Row],[Agen id]],Agen!A:C,3,0) | K2024: =TRIM(LEFT(Table3[[#This Row],[Group]],2)) | L2024: NON SALES
A2025: OP13722 | B2025: Pandawa Cell | C2025: A - Agen | D2025: OP00002 | E2025: 45493.278 | F2025: AGEN | G2025: OP13722 | H2025: =UPPER(Table3[[#This Row],[Agen id]]&"-"&VLOOKUP(Table3[[#This Row],[Agen id]],A:B,2,0)&"("&Table3[[#This Row],[Short]]&")") | J2025: =VLOOKUP(Table3[[#This Row],[Agen id]],Agen!A:C,3,0) | K2025: =TRIM(LEFT(Table3[[#This Row],[Group]],2)) | L2025: NON SALES
A2026: OP13727 | B2026: Dwi | C2026: A - Agen | D2026: 0 | E2026: 45493.54 | F2026: AGEN | G2026: OP13727 | H2026: =UPPER(Table3[[#This Row],[Agen id]]&"-"&VLOOKUP(Table3[[#This Row],[Agen id]],A:B,2,0)&"("&Table3[[#This Row],[Short]]&")") | J2026: =VLOOKUP(Table3[[#This Row],[Agen id]],Agen!A:C,3,0) | K2026: =TRIM(LEFT(Table3[[#This Row],[Group]],2)) | L2026: NON SALES
A2027: OP13729 | B2027: irma suryani | C2027: AV - Agen Verified | D2027: OP09209 | E2027: 45493.658 | F2027: DOWNLINE | G2027: OP09209 | H2027: =UPPER(Table3[[#This Row],[Agen id]]&"-"&VLOOKUP(Table3[[#This Row],[Agen id]],A:B,2,0)&"("&Table3[[#This Row],[Short]]&")") | J2027: =VLOOKUP(Table3[[#This Row],[Agen id]],Agen!A:C,3,0) | K2027: =TRIM(LEFT(Table3[[#This Row],[Group]],2)) | L2027: NON SALES
A2028: OP13736 | B2028: Lena | C2028: AV - Agen Verified | D2028: OP03783 | E2028: 45493.835 | F2028: DOWNLINE | G2028: OP03699 | H2028: =UPPER(Table3[[#This Row],[Agen id]]&"-"&VLOOKUP(Table3[[#This Row],[Agen id]],A:B,2,0)&"("&Table3[[#This Row],[Short]]&")") | J2028: =VLOOKUP(Table3[[#This Row],[Agen id]],Agen!A:C,3,0) | K2028: =TRIM(LEFT(Table3[[#This Row],[Group]],2)) | L2028: NON SALES
A2029: OP13744 | B2029: Yuyun | C2029: AV - Agen Verified | D2029: OP00002 | E2029: 45494.265 | F2029: AGEN | G2029: OP13744 | H2029: =UPPER(Table3[[#This Row],[Agen id]]&"-"&VLOOKUP(Table3[[#This Row],[Agen id]],A:B,2,0)&"("&Table3[[#This Row],[Short]]&")") | J2029: =VLOOKUP(Table3[[#This Row],[Agen id]],Agen!A:C,3,0) | K2029: =TRIM(LEFT(Table3[[#This Row],[Group]],2)) | L2029: NON SALES
A2030: OP13766 | B2030: uli | C2030: A - Agen | D2030: OP03783 | E2030: 45494.803 | F2030: DOWNLINE | G2030: OP03699 | H2030: =UPPER(Table3[[#This Row],[Agen id]]&"-"&VLOOKUP(Table3[[#This Row],[Agen id]],A:B,2,0)&"("&Table3[[#This Row],[Short]]&")") | J2030: =VLOOKUP(Table3[[#This Row],[Agen id]],Agen!A:C,3,0) | K2030: =TRIM(LEFT(Table3[[#This Row],[Group]],2)) | L2030: NON SALES
A2031: OP13770 | B2031: Lilissusilowati | C2031: AB1 - Agen Kab Bogor | D2031: OP00002 | E2031: 45494.912 | F2031: AGEN | G2031: OP13770 | H2031: =UPPER(Table3[[#This Row],[Agen id]]&"-"&VLOOKUP(Table3[[#This Row],[Agen id]],A:B,2,0)&"("&Table3[[#This Row],[Short]]&")") | J2031: =VLOOKUP(Table3[[#This Row],[Agen id]],Agen!A:C,3,0) | K2031: =TRIM(LEFT(Table3[[#This Row],[Group]],2)) | L2031: NON SALES
A2032: OP13800 | B2032: Istianah | C2032: AV - Agen Verified | D2032: OP00002 | E2032: 45495.856 | F2032: AGEN | G2032: OP13800 | H2032: =UPPER(Table3[[#This Row],[Agen id]]&"-"&VLOOKUP(Table3[[#This Row],[Agen id]],A:B,2,0)&"("&Table3[[#This Row],[Short]]&")") | J2032: =VLOOKUP(Table3[[#This Row],[Agen id]],Agen!A:C,3,0) | K2032: =TRIM(LEFT(Table3[[#This Row],[Group]],2)) | L2032: NON SALES
A2033: OP13815 | B2033: SUDI MAMPIR CELL | C2033: A - Agen | D2033: OP08075 | E2033: 45496.599 | F2033: DOWNLINE | G2033: OP08075 | H2033: =UPPER(Table3[[#This Row],[Agen id]]&"-"&VLOOKUP(Table3[[#This Row],[Agen id]],A:B,2,0)&"("&Table3[[#This Row],[Short]]&")") | J2033: =VLOOKUP(Table3[[#This Row],[Agen id]],Agen!A:C,3,0) | K2033: =TRIM(LEFT(Table3[[#This Row],[Group]],2)) | L2033: NON SALES
A2034: OP13838 | B2034: Mulyahidin | C2034: A - Agen | D2034: OP00003 | E2034: 45497.674 | F2034: AGEN | G2034: OP13838 | H2034: =UPPER(Table3[[#This Row],[Agen id]]&"-"&VLOOKUP(Table3[[#This Row],[Agen id]],A:B,2,0)&"("&Table3[[#This Row],[Short]]&")") | J2034: =VLOOKUP(Table3[[#This Row],[Agen id]],Agen!A:C,3,0) | K2034: =TRIM(LEFT(Table3[[#This Row],[Group]],2)) | L2034: NON SALES
A2035: OP13847 | B2035: juwandi | C2035: AV - Agen Verified | D2035: OP00002 | E2035: 45498.288 | F2035: AGEN | G2035: OP13847 | H2035: =UPPER(Table3[[#This Row],[Agen id]]&"-"&VLOOKUP(Table3[[#This Row],[Agen id]],A:B,2,0)&"("&Table3[[#This Row],[Short]]&")") | J2035: =VLOOKUP(Table3[[#This Row],[Agen id]],Agen!A:C,3,0) | K2035: =TRIM(LEFT(Table3[[#This Row],[Group]],2)) | L2035: NON SALES
A2036: OP13849 | B2036: Dewi Anjar | C2036: A - Agen | D2036: OP00002 | E2036: 45498.361 | F2036: AGEN | G2036: OP13849 | H2036: =UPPER(Table3[[#This Row],[Agen id]]&"-"&VLOOKUP(Table3[[#This Row],[Agen id]],A:B,2,0)&"("&Table3[[#This Row],[Short]]&")") | J2036: =VLOOKUP(Table3[[#This Row],[Agen id]],Agen!A:C,3,0) | K2036: =TRIM(LEFT(Table3[[#This Row],[Group]],2)) | L2036: NON SALES
A2037: OP13855 | B2037: Mora cell | C2037: AB1 - Agen Kab Bogor | D2037: OP00003 | E2037: 45498.581 | F2037: AGEN | G2037: OP13855 | H2037: =UPPER(Table3[[#This Row],[Agen id]]&"-"&VLOOKUP(Table3[[#This Row],[Agen id]],A:B,2,0)&"("&Table3[[#This Row],[Short]]&")") | J2037: =VLOOKUP(Table3[[#This Row],[Agen id]],Agen!A:C,3,0) | K2037: =TRIM(LEFT(Table3[[#This Row],[Group]],2)) | L2037: NON SALES
A2038: OP13865 | B2038: Laili | C2038: AV - Agen Verified | D2038: OP00002 | E2038: 45498.813 | F2038: AGEN | G2038: OP13865 | H2038: =UPPER(Table3[[#This Row],[Agen id]]&"-"&VLOOKUP(Table3[[#This Row],[Agen id]],A:B,2,0)&"("&Table3[[#This Row],[Short]]&")") | J2038: =VLOOKUP(Table3[[#This Row],[Agen id]],Agen!A:C,3,0) | K2038: =TRIM(LEFT(Table3[[#This Row],[Group]],2)) | L2038: NON SALES
... A2353: OP18810 | B2353: HERRY SAMBOH | C2353: A - Agen | D2353: OP00002 | E2353: 45826.456 | F2353: AGEN | G2353: OP18810 | H2353: =UPPER(Table3[[#This Row],[Agen id]]&"-"&VLOOKUP(Table3[[#This Row],[Agen id]],A:B,2,0)&"("&Table3[[#This Row],[Short]]&")") | J2353: =VLOOKUP(Table3[[#This Row],[Agen id]],Agen!A:C,3,0) | K2353: =TRIM(LEFT(Table3[[#This Row],[Group]],2)) | L2353: NON SALES
A2354: OP18812 | B2354: 85888217850 | C2354: A - Agen | D2354: OP00002 | E2354: 45828.378 | F2354: AGEN | G2354: OP18812 | H2354: =UPPER(Table3[[#This Row],[Agen id]]&"-"&VLOOKUP(Table3[[#This Row],[Agen id]],A:B,2,0)&"("&Table3[[#This Row],[Short]]&")") | J2354: =VLOOKUP(Table3[[#This Row],[Agen id]],Agen!A:C,3,0) | K2354: =TRIM(LEFT(Table3[[#This Row],[Group]],2)) | L2354: NON SALES
A2355: OP18813 | B2355: Intan | C2355: A - Agen | D2355: OP00002 | E2355: 45829.611 | F2355: AGEN | G2355: OP18813 | H2355: =UPPER(Table3[[#This Row],[Agen id]]&"-"&VLOOKUP(Table3[[#This Row],[Agen id]],A:B,2,0)&"("&Table3[[#This Row],[Short]]&")") | J2355: =VLOOKUP(Table3[[#This Row],[Agen id]],Agen!A:C,3,0) | K2355: =TRIM(LEFT(Table3[[#This Row],[Group]],2)) | L2355: NON SALES
A2356: OP18814 | B2356: Rezki CELL | C2356: A - Agen | D2356: OP00002 | E2356: 45830.526 | F2356: AGEN | G2356: OP18814 | H2356: =UPPER(Table3[[#This Row],[Agen id]]&"-"&VLOOKUP(Table3[[#This Row],[Agen id]],A:B,2,0)&"("&Table3[[#This Row],[Short]]&")") | J2356: =VLOOKUP(Table3[[#This Row],[Agen id]],Agen!A:C,3,0) | K2356: =TRIM(LEFT(Table3[[#This Row],[Group]],2)) | L2356: NON SALES
A2357: OP18815 | B2357: Tanjung | C2357: A - Agen | D2357: OP00002 | E2357: 45830.934 | F2357: AGEN | G2357: OP18815 | H2357: =UPPER(Table3[[#This Row],[Agen id]]&"-"&VLOOKUP(Table3[[#This Row],[Agen id]],A:B,2,0)&"("&Table3[[#This Row],[Short]]&")") | J2357: =VLOOKUP(Table3[[#This Row],[Agen id]],Agen!A:C,3,0) | K2357: =TRIM(LEFT(Table3[[#This Row],[Group]],2)) | L2357: NON SALES
A2358: OP18822 | B2358: TOKO RIYAN | C2358: AT1 - Agen Tangerang | D2358: OP07683 | E2358: 45835.603 | F2358: AGEN | G2358: OP18822 | H2358: =UPPER(Table3[[#This Row],[Agen id]]&"-"&VLOOKUP(Table3[[#This Row],[Agen id]],A:B,2,0)&"("&Table3[[#This Row],[Short]]&")") | J2358: =VLOOKUP(Table3[[#This Row],[Agen id]],Agen!A:C,3,0) | K2358: =TRIM(LEFT(Table3[[#This Row],[Group]],2)) | L2358: NON SALES
A2359: OP18823 | B2359: Lina karlina | C2359: A - Agen | D2359: OP02233 | E2359: 45835.713 | F2359: DOWNLINE | G2359: OP02233 | H2359: =UPPER(Table3[[#This Row],[Agen id]]&"-"&VLOOKUP(Table3[[#This Row],[Agen id]],A:B,2,0)&"("&Table3[[#This Row],[Short]]&")") | J2359: =VLOOKUP(Table3[[#This Row],[Agen id]],Agen!A:C,3,0) | K2359: =TRIM(LEFT(Table3[[#This Row],[Group]],2)) | L2359: NON SALES
A2360: OP18840 | B2360: Nisa | C2360: AV - Agen Verified | D2360: OP03146 | E2360: 45846.853 | F2360: DOWNLINE | G2360: OP03146 | H2360: =UPPER(Table3[[#This Row],[Agen id]]&"-"&VLOOKUP(Table3[[#This Row],[Agen id]],A:B,2,0)&"("&Table3[[#This Row],[Short]]&")") | J2360: =VLOOKUP(Table3[[#This Row],[Agen id]],Agen!A:C,3,0) | K2360: =TRIM(LEFT(Table3[[#This Row],[Group]],2)) | L2360: NON SALES
...

Sheet Agen
A1: AGEN ID | B1: AGEN NAME | C1: CABANG | D1: TYPE | E1: SCO | F1: DSO | G1: Daftar | H1: LOCATION | I1: KOTA/KAB | J1: KECAMATAN | K1: KELURAHAN | L1: JADWAL | M1: LIMIT | N1: STATUS
A2: OP00011 | B2: =VLOOKUP(A2,Reseller!G:H,2,0) | C2: ONLINE | G2: =VLOOKUP(Table4[[#This Row],[AGEN ID]],Reseller!A:E,5,0)
A3: OP00012 | B3: =VLOOKUP(A3,Reseller!G:H,2,0) | C3: ONLINE | G3: =VLOOKUP(Table4[[#This Row],[AGEN ID]],Reseller!A:E,5,0)
A4: OP00013 | B4: =VLOOKUP(A4,Reseller!G:H,2,0) | C4: ONLINE | G4: =VLOOKUP(Table4[[#This Row],[AGEN ID]],Reseller!A:E,5,0)
A5: OP00014 | B5: =VLOOKUP(A5,Reseller!G:H,2,0) | C5: ONLINE | G5: =VLOOKUP(Table4[[#This Row],[AGEN ID]],Reseller!A:E,5,0)
A6: OP00015 | B6: =VLOOKUP(A6,Reseller!G:H,2,0) | C6: ONLINE | G6: =VLOOKUP(Table4[[#This Row],[AGEN ID]],Reseller!A:E,5,0)
A7: OP00016 | B7: =VLOOKUP(A7,Reseller!G:H,2,0) | C7: ONLINE | G7: =VLOOKUP(Table4[[#This Row],[AGEN ID]],Reseller!A:E,5,0)
A8: OP00018 | B8: =VLOOKUP(A8,Reseller!G:H,2,0) | C8: ONLINE | G8: =VLOOKUP(Table4[[#This Row],[AGEN ID]],Reseller!A:E,5,0)
A9: OP00020 | B9: =VLOOKUP(A9,Reseller!G:H,2,0) | C9: ONLINE | G9: =VLOOKUP(Table4[[#This Row],[AGEN ID]],Reseller!A:E,5,0)
A10: OP00022 | B10: =VLOOKUP(A10,Reseller!G:H,2,0) | C10: ONLINE | G10: =VLOOKUP(Table4[[#This Row],[AGEN ID]],Reseller!A:E,5,0)
A11: OP00023 | B11: =VLOOKUP(A11,Reseller!G:H,2,0) | C11: ONLINE | G11: =VLOOKUP(Table4[[#This Row],[AGEN ID]],Reseller!A:E,5,0)
A12: OP00026 | B12: =VLOOKUP(A12,Reseller!G:H,2,0) | C12: ONLINE | G12: =VLOOKUP(Table4[[#This Row],[AGEN ID]],Reseller!A:E,5,0)
A13: OP00030 | B13: =VLOOKUP(A13,Reseller!G:H,2,0) | C13: ONLINE | G13: =VLOOKUP(Table4[[#This Row],[AGEN ID]],Reseller!A:E,5,0)
... A1703: OP19727 | B1703: =VLOOKUP(A1703,Reseller!G:H,2,0) | C1703: ONLINE | G1703: =VLOOKUP(Table4[[#This Row],[AGEN ID]],Reseller!A:E,5,0)
